#VRML_SIM R2022a utf8
WorldInfo {
}
Viewpoint {
  orientation 0.16860595065475473 -0.715498649409611 -0.6779629164613867 5.614145920665114
  position -11.003083788020755 -9.608705753345651 6.806291638615431
  followType "None"
}
Background {
  skyColor [
    0.388235 0.662745 1
  ]
}
Solid {
  children [
    Solid {
      translation -2.5 0 0.5
      rotation 0 1 0 1.5708
      children [
        Shape {
          appearance DEF walls MattePaint {
            baseColor 0 0.156863 0.231373
          }
          geometry DEF wallPlane Plane {
            size 1 15
          }
        }
      ]
      name "Wall"
      boundingObject USE wallPlane
    }
    Solid {
      rotation 0 1 0 0
      children [
        Shape {
          appearance MattePaint {
            baseColor 0.0784314 0.0784314 0.0784314
          }
          geometry DEF groundPlane Plane {
            size 5 15
          }
        }
      ]
      name "Ground"
      boundingObject USE groundPlane
    }
    Solid {
      translation 2.5 0 0.5
      rotation 0.70710528118436 3.3905113482557537e-09 -0.707108281185553 3.14159
      children [
        Shape {
          appearance USE walls
          geometry DEF wallPlane Plane {
            size 1 15
          }
        }
      ]
      name "Wall(1)"
      boundingObject USE wallPlane
    }
    Solid {
      translation 0 7.5 0.5
      rotation 0.5773489358556708 0.5773509358554485 -0.5773509358554485 2.0944
      children [
        Shape {
          appearance USE walls
          geometry DEF wallPlane Plane {
            size 1 5
          }
        }
      ]
      name "Wall(2)"
      boundingObject USE wallPlane
    }
    Solid {
      translation 0 -7.5 0.5
      rotation 0.5773476025217157 -0.5773516025189619 -0.5773516025189619 -2.094395307179586
      children [
        Shape {
          appearance USE walls
          geometry DEF wallPlane Plane {
            size 1 5
          }
        }
      ]
      name "Wall(3)"
      boundingObject USE wallPlane
    }
  ]
  name "Stadium"
}
Solid {
  translation 1.5 0 0.5
  children [
    Shape {
      appearance USE walls
      geometry DEF midwall Box {
        size 2 0.1 1
      }
    }
  ]
  name "MidWall"
  boundingObject USE midwall
}
Solid {
  translation -1.5 0 0.5
  children [
    Shape {
      appearance USE walls
      geometry DEF midwall Box {
        size 2 0.1 1
      }
    }
  ]
  name "MidWall(1)"
  boundingObject USE midwall
}
Solid {
  translation 0 -2.52 0.5
  children [
    Shape {
      appearance MattePaint {
        baseColor 1 0 0
      }
      geometry DEF obstacleBox Box {
        size 1 1 1
      }
    }
  ]
  name "obstacleBox"
  boundingObject USE obstacleBox
  physics Physics {
    density 0.01
  }
}
Robot {
  translation 0.0764612 -4.17421 0.3
  children [
    DistanceSensor {
      translation 0.05 0.2 0
      rotation 0 0 1 1.309
      name "rightTouchSensor"
      lookupTable [
        0 1 0
        0.05 0 0
      ]
    }
    DistanceSensor {
      translation -0.05 0.2 0
      rotation 0 0 1 1.8326
      name "leftTouchSensor"
      lookupTable [
        0 1 0
        0.05 0 0
      ]
    }
    LED {
      translation -0.19 0 0.051
      rotation 1 0 0 1.5708
      children [
        Shape {
          appearance PBRAppearance {
            baseColor 0 0 0
          }
          geometry Box {
            size 0.01 0.01 0.01
          }
          castShadows FALSE
        }
      ]
      name "leftMotorIndicator"
      color [
        0 1 0
      ]
      gradual TRUE
    }
    LED {
      translation 0.19 0 0.051
      rotation 1 0 0 1.5708
      children [
        Shape {
          appearance PBRAppearance {
            baseColor 0 0 0
          }
          geometry Box {
            size 0.01 0.01 0.01
          }
          castShadows FALSE
        }
      ]
      name "rightMotorIndicator"
      color [
        0 1 0
      ]
      gradual TRUE
    }
    Transform {
      translation 0 0.201 0.03
      children [
        SpotLight {
          attenuation 0 0 1
          beamWidth 0.7
          direction 0 1 0
        }
      ]
    }
    Camera {
      translation 0 0.187 0
      rotation 0 0 1 1.5708
      width 6
      height 6
    }
    HingeJoint {
      jointParameters HingeJointParameters {
        axis -1 0 0
        anchor -0.212 0 -0.005
      }
      device [
        RotationalMotor {
          name "leftMotor"
          maxTorque 100
        }
      ]
      endPoint Solid {
        translation -0.212 0 -0.005
        rotation 1.5700895750559073e-15 1 -1.5700895750559076e-16 1.5707999999999942
        children [
          DEF wheel Shape {
            appearance Rubber {
            }
            geometry DEF wheelGeom Cylinder {
              height 0.02
              radius 0.05
            }
          }
        ]
        name "wheelLeft"
        boundingObject USE wheelGeom
        physics Physics {
          density 1
        }
      }
    }
    HingeJoint {
      jointParameters HingeJointParameters {
        axis -1 0 0
        anchor 0.212 0 -0.005
      }
      device [
        RotationalMotor {
          name "rightMotor"
          maxTorque 100
        }
      ]
      endPoint Solid {
        translation 0.212 0 -0.005
        rotation 1.3345761387975212e-15 1 7.850447875279537e-17 1.5707999999999944
        children [
          DEF wheel Shape {
            appearance Rubber {
            }
            geometry DEF wheelGeom Cylinder {
              height 0.02
              radius 0.05
            }
          }
        ]
        name "wheelLeft(1)"
        boundingObject USE wheelGeom
        physics Physics {
          density 1
        }
      }
    }
    Shape {
      appearance MattePaint {
        baseColor 0 0.0470588 0.929412
      }
      geometry DEF puck_body Cylinder {
        height 0.1
        radius 0.2
      }
    }
  ]
  name "puck cam"
  boundingObject USE puck_body
  physics Physics {
    density 1
  }
  controller "camController"
}
