#VRML_SIM R2022a utf8
WorldInfo {
  basicTimeStep 16
}
Viewpoint {
  orientation 0.10915383596731007 0.6158297215858822 -0.7802814838922403 0.6373016326293056
  position -1.3727462892594033 0.4346918436266305 0.705985429411673
}
TexturedBackground {
}
TexturedBackgroundLight {
}
RectangleArena {
}
WoodenBox {
  translation 0 0.19 0.07
  size 0.1 0.1 0.1
  mass 1
}
WoodenBox {
  translation 0.25 -0.16 0.07
  name "wooden box(1)"
  size 0.1 0.1 0.1
  mass 1
}
WoodenBox {
  translation -0.25 -0.02 0.07
  name "wooden box(2)"
  size 0.1 0.1 0.1
  mass 1
}
Robot {
  translation 0 -0.4 0.05
  children [
    Camera {
      rotation 0 0 1 1.5708
      width 6
      height 6
    }
    HingeJoint {
      jointParameters HingeJointParameters {
        axis -1 0 0
        anchor -0.057 0 -0.002
      }
      device [
        RotationalMotor {
          name "leftMotor"
        }
      ]
      endPoint Solid {
        translation -0.057 0 -0.002
        rotation 9.8130598440994e-18 1 8.83175385968946e-17 1.570799999999999
        children [
          DEF wheel Shape {
            appearance PaintedWood {
              colorOverride 0.427451 0.192157 0.192157
            }
            geometry Cylinder {
              height 0.01
              radius 0.015
            }
          }
        ]
        name "wheelLeft"
        boundingObject USE wheel
        physics Physics {
        }
      }
    }
    HingeJoint {
      jointParameters HingeJointParameters {
        axis -1 0 0
        anchor 0.057 0 -0.002
      }
      device [
        RotationalMotor {
          name "rightMotor"
        }
      ]
      endPoint Solid {
        translation 0.057 0 -0.002
        rotation -3.140179150111809e-16 1 0 1.5707999999999984
        children [
          DEF wheel Shape {
            appearance PaintedWood {
              colorOverride 0.427451 0.192157 0.192157
            }
            geometry Cylinder {
              height 0.01
              radius 0.015
            }
          }
        ]
        name "wheelRight"
        boundingObject USE wheel
        physics Physics {
        }
      }
    }
    Shape {
      appearance GlossyPaint {
        baseColor 0.305882 0.32549 0.447059
      }
      geometry DEF puck_body Cylinder {
        height 0.03
        radius 0.05
      }
    }
  ]
  name "puck cam"
  boundingObject USE puck_body
  physics Physics {
  }
  controller "camController"
}
