#VRML_SIM R2022a utf8
WorldInfo {
}
Viewpoint {
  orientation 0.38595445936056133 0.006097169906391297 -0.9224976855357575 3.1124481426039763
  position 11.628042717187654 -1.3869064528432684 12.346117407848068
  follow "puck cam"
}
Background {
  skyColor [
    0.215686 0.254902 0.215686
    0 0 0
    0 0 0
  ]
}
DirectionalLight {
  direction 0 -1 -1
}
Solid {
  children [
    Solid {
      rotation 0 1 0 0
      children [
        Shape {
          appearance Pavement {
            type "tiles"
            textureTransform TextureTransform {
              scale 2 4
            }
          }
          geometry DEF groundPlane Plane {
            size 5 15
          }
        }
      ]
      name "Ground"
      boundingObject USE groundPlane
    }
    Solid {
      translation -2.5 0 0.5
      rotation 0 1 0 1.5708
      children [
        Shape {
          appearance MattePaint {
            baseColor 0 0.156863 0.231373
          }
          geometry DEF wallPlane Plane {
            size 1 15
          }
        }
      ]
      name "Wall"
      boundingObject USE wallPlane
    }
    Solid {
      translation 2.5 0 0.5
      rotation 0.70710528118436 3.3905113482557537e-09 -0.707108281185553 3.14159
      children [
        Shape {
          appearance MattePaint {
            baseColor 0 0.156863 0.231373
          }
          geometry DEF wallPlane Plane {
            size 1 15
          }
        }
      ]
      name "Wall(1)"
      boundingObject USE wallPlane
    }
    Solid {
      translation 0 7.5 0.5
      rotation 0.5773489358556708 0.5773509358554485 -0.5773509358554485 2.0944
      children [
        Shape {
          appearance MattePaint {
            baseColor 0 0.156863 0.231373
          }
          geometry DEF wallPlane Plane {
            size 1 5
          }
        }
      ]
      name "Wall(2)"
      boundingObject USE wallPlane
    }
    Solid {
      translation 0 -7.5 0.5
      rotation 0.5773476025217157 -0.5773516025189619 -0.5773516025189619 -2.094395307179586
      children [
        Shape {
          appearance MattePaint {
            baseColor 0 0.156863 0.231373
          }
          geometry DEF wallPlane Plane {
            size 1 5
          }
        }
      ]
      name "Wall(3)"
      boundingObject USE wallPlane
    }
  ]
  name "Stadium"
}
Robot {
  translation 0 -7 0.1
  children [
    DistanceSensor {
      translation 0.05 0.2 0
      rotation 0 0 1 1.309
      name "rightTouchSensor"
      lookupTable [
        0 1 0
        4 0 0
      ]
    }
    DistanceSensor {
      translation -0.05 0.2 0
      rotation 0 0 1 1.8326
      name "leftTouchSensor"
      lookupTable [
        0 1 0
        4 0 0
      ]
    }
    LED {
      translation -0.18 0 0.05
      rotation 1 0 0 1.5708
      children [
        Shape {
          appearance PBRAppearance {
            baseColor 0 0 0
          }
          geometry Box {
            size 0.03 0.01 0.03
          }
        }
      ]
      name "leftMotorIndicator"
      color []
      gradual TRUE
    }
    LED {
      translation 0.18 0 0.05
      rotation 1 0 0 1.5708
      children [
        Shape {
          appearance PBRAppearance {
            baseColor 0 0 0
          }
          geometry Box {
            size 0.03 0.01 0.03
          }
        }
      ]
      name "rightMotorIndicator"
      color []
      gradual TRUE
    }
    Transform {
      translation 0 0.201 0.03
      children [
        SpotLight {
          attenuation 0 0 1
          beamWidth 0.7
          direction 0 1 0
        }
      ]
    }
    HingeJoint {
      jointParameters HingeJointParameters {
        axis -1 0 0
        anchor -0.212 0 -0.005
      }
      device [
        RotationalMotor {
          name "leftMotor"
          maxTorque 100
        }
      ]
      endPoint Solid {
        translation -0.212 0 -0.005
        rotation 1.4327067372385162e-15 1 0 1.5707999999999944
        children [
          DEF wheel Shape {
            appearance Rubber {
            }
            geometry DEF wheelGeom Cylinder {
              height 0.02
              radius 0.05
            }
          }
        ]
        name "wheelLeft"
        boundingObject USE wheelGeom
        physics Physics {
          density 1
        }
      }
    }
    HingeJoint {
      jointParameters HingeJointParameters {
        axis -1 0 0
        anchor 0.212 0 -0.005
      }
      device [
        RotationalMotor {
          name "rightMotor"
          maxTorque 100
        }
      ]
      endPoint Solid {
        translation 0.212 0 -0.005
        rotation 1.4327067372385162e-15 1 0 1.5707999999999944
        children [
          DEF wheel Shape {
            appearance Rubber {
            }
            geometry DEF wheelGeom Cylinder {
              height 0.02
              radius 0.05
            }
          }
        ]
        name "wheelLeft(1)"
        boundingObject USE wheelGeom
        physics Physics {
          density 1
        }
      }
    }
    Shape {
      appearance MattePaint {
        baseColor 0 0.0470588 0.929412
      }
      geometry DEF puck_body Cylinder {
        height 0.1
        radius 0.2
      }
    }
  ]
  name "puck cam"
  boundingObject USE puck_body
  physics Physics {
    density 1
  }
  controller "simpleLearningController"
  supervisor TRUE
}
Robot {
  translation 0.5 -7 0.1
  children [
    DistanceSensor {
      translation 0.05 0.2 0
      rotation 0 0 1 1.309
      name "rightTouchSensor"
      lookupTable [
        0 1 0
        4 0 0
      ]
    }
    DistanceSensor {
      translation -0.05 0.2 0
      rotation 0 0 1 1.8326
      name "leftTouchSensor"
      lookupTable [
        0 1 0
        4 0 0
      ]
    }
    LED {
      translation -0.18 0 0.05
      rotation 1 0 0 1.5708
      children [
        Shape {
          appearance PBRAppearance {
            baseColor 0 0 0
          }
          geometry Box {
            size 0.03 0.01 0.03
          }
        }
      ]
      name "leftMotorIndicator"
      color []
      gradual TRUE
    }
    LED {
      translation 0.18 0 0.05
      rotation 1 0 0 1.5708
      children [
        Shape {
          appearance PBRAppearance {
            baseColor 0 0 0
          }
          geometry Box {
            size 0.03 0.01 0.03
          }
        }
      ]
      name "rightMotorIndicator"
      color []
      gradual TRUE
    }
    Transform {
      translation 0 0.201 0.03
      children [
        SpotLight {
          attenuation 0 0 1
          beamWidth 0.7
          direction 0 1 0
        }
      ]
    }
    HingeJoint {
      jointParameters HingeJointParameters {
        axis -1 0 0
        anchor -0.212 0 -0.005
      }
      device [
        RotationalMotor {
          name "leftMotor"
          maxTorque 100
        }
      ]
      endPoint Solid {
        translation -0.212 0 -0.005
        rotation 1.4327067372385162e-15 1 0 1.5707999999999944
        children [
          DEF wheel Shape {
            appearance Rubber {
            }
            geometry DEF wheelGeom Cylinder {
              height 0.02
              radius 0.05
            }
          }
        ]
        name "wheelLeft"
        boundingObject USE wheelGeom
        physics Physics {
          density 1
        }
      }
    }
    HingeJoint {
      jointParameters HingeJointParameters {
        axis -1 0 0
        anchor 0.212 0 -0.005
      }
      device [
        RotationalMotor {
          name "rightMotor"
          maxTorque 100
        }
      ]
      endPoint Solid {
        translation 0.212 0 -0.005
        rotation 1.4327067372385162e-15 1 0 1.5707999999999944
        children [
          DEF wheel Shape {
            appearance Rubber {
            }
            geometry DEF wheelGeom Cylinder {
              height 0.02
              radius 0.05
            }
          }
        ]
        name "wheelLeft(1)"
        boundingObject USE wheelGeom
        physics Physics {
          density 1
        }
      }
    }
    Shape {
      appearance MattePaint {
        baseColor 0 0.0470588 0.929412
      }
      geometry DEF puck_body Cylinder {
        height 0.1
        radius 0.2
      }
    }
  ]
  name "puck cam(1)"
  boundingObject USE puck_body
  physics Physics {
    density 1
  }
  controller "simpleLearningController"
  supervisor TRUE
}
Robot {
  translation -0.5 -7 0.1
  children [
    DistanceSensor {
      translation 0.05 0.2 0
      rotation 0 0 1 1.309
      name "rightTouchSensor"
      lookupTable [
        0 1 0
        4 0 0
      ]
    }
    DistanceSensor {
      translation -0.05 0.2 0
      rotation 0 0 1 1.8326
      name "leftTouchSensor"
      lookupTable [
        0 1 0
        4 0 0
      ]
    }
    LED {
      translation -0.18 0 0.05
      rotation 1 0 0 1.5708
      children [
        Shape {
          appearance PBRAppearance {
            baseColor 0 0 0
          }
          geometry Box {
            size 0.03 0.01 0.03
          }
        }
      ]
      name "leftMotorIndicator"
      color []
      gradual TRUE
    }
    LED {
      translation 0.18 0 0.05
      rotation 1 0 0 1.5708
      children [
        Shape {
          appearance PBRAppearance {
            baseColor 0 0 0
          }
          geometry Box {
            size 0.03 0.01 0.03
          }
        }
      ]
      name "rightMotorIndicator"
      color []
      gradual TRUE
    }
    Transform {
      translation 0 0.201 0.03
      children [
        SpotLight {
          attenuation 0 0 1
          beamWidth 0.7
          direction 0 1 0
        }
      ]
    }
    HingeJoint {
      jointParameters HingeJointParameters {
        axis -1 0 0
        anchor -0.212 0 -0.005
      }
      device [
        RotationalMotor {
          name "leftMotor"
          maxTorque 100
        }
      ]
      endPoint Solid {
        translation -0.212 0 -0.005
        rotation 1.4327067372385162e-15 1 0 1.5707999999999944
        children [
          DEF wheel Shape {
            appearance Rubber {
            }
            geometry DEF wheelGeom Cylinder {
              height 0.02
              radius 0.05
            }
          }
        ]
        name "wheelLeft"
        boundingObject USE wheelGeom
        physics Physics {
          density 1
        }
      }
    }
    HingeJoint {
      jointParameters HingeJointParameters {
        axis -1 0 0
        anchor 0.212 0 -0.005
      }
      device [
        RotationalMotor {
          name "rightMotor"
          maxTorque 100
        }
      ]
      endPoint Solid {
        translation 0.212 0 -0.005
        rotation 1.4327067372385162e-15 1 0 1.5707999999999944
        children [
          DEF wheel Shape {
            appearance Rubber {
            }
            geometry DEF wheelGeom Cylinder {
              height 0.02
              radius 0.05
            }
          }
        ]
        name "wheelLeft(1)"
        boundingObject USE wheelGeom
        physics Physics {
          density 1
        }
      }
    }
    Shape {
      appearance MattePaint {
        baseColor 0 0.0470588 0.929412
      }
      geometry DEF puck_body Cylinder {
        height 0.1
        radius 0.2
      }
    }
  ]
  name "puck cam(2)"
  boundingObject USE puck_body
  physics Physics {
    density 1
  }
  controller "simpleLearningController"
  supervisor TRUE
}
Robot {
  translation 1 -7 0.1
  children [
    DistanceSensor {
      translation 0.05 0.2 0
      rotation 0 0 1 1.309
      name "rightTouchSensor"
      lookupTable [
        0 1 0
        4 0 0
      ]
    }
    DistanceSensor {
      translation -0.05 0.2 0
      rotation 0 0 1 1.8326
      name "leftTouchSensor"
      lookupTable [
        0 1 0
        4 0 0
      ]
    }
    LED {
      translation -0.18 0 0.05
      rotation 1 0 0 1.5708
      children [
        Shape {
          appearance PBRAppearance {
            baseColor 0 0 0
          }
          geometry Box {
            size 0.03 0.01 0.03
          }
        }
      ]
      name "leftMotorIndicator"
      color []
      gradual TRUE
    }
    LED {
      translation 0.18 0 0.05
      rotation 1 0 0 1.5708
      children [
        Shape {
          appearance PBRAppearance {
            baseColor 0 0 0
          }
          geometry Box {
            size 0.03 0.01 0.03
          }
        }
      ]
      name "rightMotorIndicator"
      color []
      gradual TRUE
    }
    Transform {
      translation 0 0.201 0.03
      children [
        SpotLight {
          attenuation 0 0 1
          beamWidth 0.7
          direction 0 1 0
        }
      ]
    }
    HingeJoint {
      jointParameters HingeJointParameters {
        axis -1 0 0
        anchor -0.212 0 -0.005
      }
      device [
        RotationalMotor {
          name "leftMotor"
          maxTorque 100
        }
      ]
      endPoint Solid {
        translation -0.212 0 -0.005
        rotation 1.4327067372385162e-15 1 0 1.5707999999999944
        children [
          DEF wheel Shape {
            appearance Rubber {
            }
            geometry DEF wheelGeom Cylinder {
              height 0.02
              radius 0.05
            }
          }
        ]
        name "wheelLeft"
        boundingObject USE wheelGeom
        physics Physics {
          density 1
        }
      }
    }
    HingeJoint {
      jointParameters HingeJointParameters {
        axis -1 0 0
        anchor 0.212 0 -0.005
      }
      device [
        RotationalMotor {
          name "rightMotor"
          maxTorque 100
        }
      ]
      endPoint Solid {
        translation 0.212 0 -0.005
        rotation 1.4327067372385162e-15 1 0 1.5707999999999944
        children [
          DEF wheel Shape {
            appearance Rubber {
            }
            geometry DEF wheelGeom Cylinder {
              height 0.02
              radius 0.05
            }
          }
        ]
        name "wheelLeft(1)"
        boundingObject USE wheelGeom
        physics Physics {
          density 1
        }
      }
    }
    Shape {
      appearance MattePaint {
        baseColor 0 0.0470588 0.929412
      }
      geometry DEF puck_body Cylinder {
        height 0.1
        radius 0.2
      }
    }
  ]
  name "puck cam(3)"
  boundingObject USE puck_body
  physics Physics {
    density 1
  }
  controller "simpleLearningController"
  supervisor TRUE
}
DEF goal Ball {
  translation 0 5.62 0.12
}
